Workbook

Sheet README
A1: SUPERWOOD × Data Centers — material mass, embodied carbon and replacement model (2026-09-04, v3)
A3: Reference unit: 1 GW IT-load data center. Change any yellow cell on Inputs (and the four addressable-share columns on 1 GW data center — immediate, soon, medium term, long term; a row may split across them); everything recalculates.
A4: Low column = every low input; High column = every high input. These are scenario bounds, not a distribution — vary single inputs for sensitivities.
A6: Read the sheet 1 GW data center top to bottom: building structure and envelope first, then contents, with a running cumulative total. The right-hand columns show, for each component, the addressable share in each of the four horizons, the mass replaced, and the SUPERWOOD required (per-horizon SUPERWOOD split sits in grouped helper columns P–W). The summary block and chart follow.
A7: Horizons: Immediate (shipping now, no assembly rating) · Soon (certification-gated non-structural: platforms, railings, barriers, racking, doors) · Medium term (structural steel, roof trusses and roofs, ducting, enclosures) · Long term (foundations). Switch Inputs walls_precast to 1 to model precast perimeter walls; foundation_share and conc_sub_factor drive the long-term row.
A9: Provenance: concrete and structural-steel intensities are published, secondary (arXiv 2509.21312 citing Hasan 2022 / Sharma 2023, conf M); GB200 rack mass is NVIDIA-published (conf H). Everything else is estimated [conf: L] — replace with a real material takeoff from HITT, Turner or Fast + Epp before external use.
A10: Embodied carbon: columns X–AB on the main sheet value each row at its own factor (concrete, steel, mixed; equipment not estimated), with totals and steel/concrete shares in the summary; the Carbon sheet rolls avoided emissions up by horizon at those factors and at the recycled-steel (EAF) factor. Steel share: the Steel share sheet estimates what fraction of above-ground mass, contents included, is steel (per-component steel fractions are yellow inputs).
A11: Companion narrative: materials-mass-and-replacement.md in the same folder.

Sheet Inputs
A1: Parameter | B1: Low | C1: High | D1: Unit | E1: Label / confidence | F1: Note
A2: IT load of reference data center | B2: 1000 | C2: 1000 | D2: MW | E2: assumption | F2: Everything downstream is linear in this
A3: Building area per MW | B3: 5000 | C3: 10000 | D3: sf/MW | E3: estimated [L] | F3: Hyperscale, single-story
A4: Footprint per building | B4: 1000000 | C4: 1000000 | D4: sf | E4: estimated [L] | F4: ~1,000 ft sides
A5: Exterior wall area per building | B5: 160000 | C5: 160000 | D5: sf | E5: derived | F5: 4 × 1,000 ft × 40 ft eave
A6: Yard / mechanical screens and louvers (per data center) | B6: 200000 | C6: 500000 | D6: sf | E6: estimated [L]
A7: Perimeter + yard fence length | B7: 10 | C7: 20 | D7: km | E7: estimated [L] | F7: Data center perimeter plus transformer / generator yards
A8: Fence height | B8: 2.5 | C8: 2.5 | D8: m | E8: assumption
A9: Biophilic interior paneling (admin / office wings) | B9: 100000 | C9: 300000 | D9: sf | E9: estimated [L]
A10: Backplanes, trim, door kicks, sub-framing | B10: 50000 | C10: 150000 | D10: sf | E10: estimated [L]
A11: Concrete intensity (all concrete) | B11: 500 | C11: 1000 | D11: m³/MW | E11: published, secondary [M] | F11: arXiv 2509.21312 citing Hasan 2022 / Sharma 2023: 5,000–10,000 m³ per 10 MW
A12: Concrete density | B12: 2.4 | C12: 2.4 | D12: t/m³ | E12: published [H]
A13: Walls are precast? (1 = yes, 0 = metal panel) | B13: 0 | C13: 0 | D13: flag | E13: choice | F13: 1: facade mass moves from metal skins (immediate) to precast panels (long term)
A14: Precast / tilt-up wall thickness | B14: 0.2 | C14: 0.2 | D14: m | E14: estimated [L] | F14: 8 in
A15: Structural steel intensity | B15: 50 | C15: 100 | D15: t/MW | E15: published, secondary [M] | F15: Same source: 500–1,000 t per 10 MW
A16: Share of structural steel that is secondary (trusses, joists, girts, deck) | B16: 0.4 | C16: 0.6 | D16: share | E16: estimated [L] | F16: Remainder = primary frame
A17: Rebar per m³ of concrete | B17: 60 | C17: 100 | D17: kg/m³ | E17: estimated [L]
A18: Platforms, walkways, mezzanines, railings, tray supports | B18: 5 | C18: 15 | D18: t/MW | E18: estimated [L]
A19: Metal panel / IMP cladding mass | B19: 25 | C19: 50 | D19: kg/m² | E19: estimated [L]
A20: Louver / screen system mass | B20: 10 | C20: 20 | D20: kg/m² | E20: estimated [L]
A21: Steel fence mass per running metre | B21: 30 | C21: 50 | D21: kg/m | E21: estimated [L] | F21: Palisade / chain-link with posts
A22: Acoustic barriers, enclosures, HVAC separations | B22: 2 | C22: 5 | D22: t/MW | E22: estimated [L]
A23: Racking and equipment supports | B23: 2 | C23: 5 | D23: t/MW | E23: estimated [L]
A24: Other tray, containment, doors, misc. metals | B24: 5 | C24: 10 | D24: t/MW | E24: estimated [L]
A25: Interior finishes, backplanes, trim (mass) | B25: 1 | C25: 3 | D25: t/MW | E25: estimated [L] | F25: Admin / office wings only
A26: Electrical: gensets, transformers, switchgear, UPS, busway, copper | B26: 50 | C26: 100 | D26: t/MW | E26: estimated [L] | F26: Genset 30–60 t, 1 MW UPS 10–20 t, transformer 5–8 t
A27: Mechanical: chillers, fan walls, coolers, piping, water | B27: 20 | C27: 50 | D27: t/MW | E27: estimated [L]
A28: IT: servers and racks | B28: 15 | C28: 70 | D28: t/MW | E28: estimated [L] | F28: Loaded rack ~1 t; GB200 NVL72 ~1.36 t [H]
A29: Share of IT mass that is server and equipment enclosures (boxes), replaceable long term | B29: 0.4 | C29: 0.4 | D29: share | E29: estimated [L]; Alex 2026-09-04 | F29: Server boxes eventually; the electronics never
A30: Share of all concrete that is foundations, footings, piers and equipment pads | B30: 0.4 | C30: 0.5 | D30: share | E30: estimated [L] | F30: Remainder is slab on grade, paving and yard
A31: Long-term technical potential: share of slab-on-grade and paving concrete replaceable | B31: 0.75 | C31: 0.75 | D31: share | E31: asserted-internal (Alex, 2026-09-01) [L] | F31: Technical potential, not a plan; no design or code pathway yet
A32: Long-term technical potential: share of foundations, footings, piers and pads replaceable | B32: 0.9 | C32: 0.9 | D32: share | E32: asserted-internal (Alex, 2026-09-01) [L] | F32: Technical potential, not a plan
A33: kg SUPERWOOD per kg of concrete replaced | B33: 0.05 | C33: 0.15 | D33: kg/kg | E33: estimated [L] | F33: Lightweight insulated wood-foundation concept; no design exists yet
A34: Ducting, plenums and air-distribution sheet metal | B34: 3 | C34: 8 | D34: t/MW | E34: estimated [L] | F34: Separate from the mechanical-equipment row
A35: Concrete emissions | B35: 0.12 | C35: 0.12 | D35: kg CO₂e/kg | E35: industry range [M] | F35: Ready-mix, cradle to gate; typical 0.10–0.15
A36: SUPERWOOD average board thickness | B36: 7.2 | C36: 7.2 | D36: mm | E36: internal TEM basis [H]
A37: SUPERWOOD density | B37: 1300 | C37: 1300 | D37: kg/m³ | E37: internal TEM [H]
A38: SuperMill One output | B38: 1000000 | C38: 1000000 | D38: sf/yr | E38: internal [H]
A39: SuperMill Two output | B39: 36000000 | C39: 36000000 | D39: sf/yr | E39: internal [H]
A40: Structural substitution: kg SUPERWOOD per kg steel replaced | B40: 0.3 | C40: 0.6 | D40: kg/kg | E40: estimated [L] | F40: Engineering-stamped per element (Fast + Epp) before external use
...

Sheet 1 GW data center
A1: Component (building, then contents) | B1: Low tons per data center | C1: High tons per data center | D1: Low cumulative t | E1: High cumulative t | F1: Addressable — immediate | G1: Addressable — soon | H1: Addressable — medium term | I1: Addressable — long term | J1: Low replaced t | K1: High replaced t | L1: Low SUPERWOOD t | M1: High SUPERWOOD t | N1: Gate / basis | O1: High not replaced t | P1: Low SW immediate (helper — grouped, unhide to see the per-horizon split) | Q1: Low SW soon | R1: Low SW medium | S1: Low SW long | T1: High SW immediate | U1: High SW soon | V1: High SW medium | W1: High SW long | X1: Carbon factor (kg CO₂e/kg) | Y1: Low embodied carbon (t CO₂e) | Z1: High embodied carbon (t CO₂e) | AA1: EAF-basis factor (kg CO₂e/kg) | AB1: Material class
A2: BUILDING — STRUCTURE AND ENVELOPE
A3: Concrete: slab on grade, paving, yard | B3: =Inputs!$B$11*(1-Inputs!$B$30)*Inputs!$B$12*Inputs!$B$2-B5 | C3: =Inputs!$C$11*(1-Inputs!$C$30)*Inputs!$C$12*Inputs!$C$2-C5 | D3: =B3 | E3: =C3 | F3: 0 | G3: 0 | H3: 0 | I3: =Inputs!$B$31 | J3: =B3*SUM($F3:$I3) | K3: =C3*SUM($F3:$I3) | L3: =J3*Inputs!$B$33 | M3: =K3*Inputs!$C$33 | N3: Technical potential per Alex (75%); no design or code pathway yet. arXiv 2509.21312 [M] for total concrete | O3: =C3-K3 | P3: =IF(SUM($F3:$I3)=0,0,L3*F3/SUM($F3:$I3)) | Q3: =IF(SUM($F3:$I3)=0,0,L3*G3/SUM($F3:$I3)) | R3: =IF(SUM($F3:$I3)=0,0,L3*H3/SUM($F3:$I3)) | S3: =IF(SUM($F3:$I3)=0,0,L3*I3/SUM($F3:$I3)) | T3: =IF(SUM($F3:$I3)=0,0,M3*F3/SUM($F3:$I3)) | U3: =IF(SUM($F3:$I3)=0,0,M3*G3/SUM($F3:$I3)) | V3: =IF(SUM($F3:$I3)=0,0,M3*H3/SUM($F3:$I3)) | W3: =IF(SUM($F3:$I3)=0,0,M3*I3/SUM($F3:$I3)) | X3: =Inputs!$B$35 | Y3: =B3*X3 | Z3: =C3*X3 | AA3: =Inputs!$B$35 | AB3: concrete
A4: Concrete: foundations, footings, piers, equipment pads | B4: =Inputs!$B$11*Inputs!$B$30*Inputs!$B$12*Inputs!$B$2 | C4: =Inputs!$C$11*Inputs!$C$30*Inputs!$C$12*Inputs!$C$2 | D4: =D3+B4 | E4: =E3+C4 | F4: 0 | G4: 0 | H4: 0 | I4: =Inputs!$B$32 | J4: =B4*SUM($F4:$I4) | K4: =C4*SUM($F4:$I4) | L4: =J4*Inputs!$B$33 | M4: =K4*Inputs!$C$33 | N4: Technical potential per Alex (90%); lightweight insulated SUPERWOOD foundations — geotechnical, durability and code pathway all open | O4: =C4-K4 | P4: =IF(SUM($F4:$I4)=0,0,L4*F4/SUM($F4:$I4)) | Q4: =IF(SUM($F4:$I4)=0,0,L4*G4/SUM($F4:$I4)) | R4: =IF(SUM($F4:$I4)=0,0,L4*H4/SUM($F4:$I4)) | S4: =IF(SUM($F4:$I4)=0,0,L4*I4/SUM($F4:$I4)) | T4: =IF(SUM($F4:$I4)=0,0,M4*F4/SUM($F4:$I4)) | U4: =IF(SUM($F4:$I4)=0,0,M4*G4/SUM($F4:$I4)) | V4: =IF(SUM($F4:$I4)=0,0,M4*H4/SUM($F4:$I4)) | W4: =IF(SUM($F4:$I4)=0,0,M4*I4/SUM($F4:$I4)) | X4: =Inputs!$B$35 | Y4: =B4*X4 | Z4: =C4*X4 | AA4: =Inputs!$B$35 | AB4: concrete
A5: Precast / tilt-up perimeter walls (precast case) | B5: =Inputs!$B$13*Derived!B4*Inputs!$B$14*Inputs!$B$12 | C5: =Inputs!$C$13*Derived!C4*Inputs!$C$14*Inputs!$C$12 | D5: =D4+B5 | E5: =E4+C5 | F5: 0 | G5: 0 | H5: 1 | I5: 0 | J5: =B5*SUM($F5:$I5) | K5: =C5*SUM($F5:$I5) | L5: =SUM($F5:$I5)*Inputs!$B$13*Derived!B4*Inputs!$B$41/1000 | M5: =SUM($F5:$I5)*Inputs!$C$13*Derived!C4*Inputs!$C$41/1000 | N5: Hybrid SUPERWOOD wall panels; NFPA 285 + E119 assemblies. Active when Inputs walls_precast = 1 | O5: =C5-K5 | P5: =IF(SUM($F5:$I5)=0,0,L5*F5/SUM($F5:$I5)) | Q5: =IF(SUM($F5:$I5)=0,0,L5*G5/SUM($F5:$I5)) | R5: =IF(SUM($F5:$I5)=0,0,L5*H5/SUM($F5:$I5)) | S5: =IF(SUM($F5:$I5)=0,0,L5*I5/SUM($F5:$I5)) | T5: =IF(SUM($F5:$I5)=0,0,M5*F5/SUM($F5:$I5)) | U5: =IF(SUM($F5:$I5)=0,0,M5*G5/SUM($F5:$I5)) | V5: =IF(SUM($F5:$I5)=0,0,M5*H5/SUM($F5:$I5)) | W5: =IF(SUM($F5:$I5)=0,0,M5*I5/SUM($F5:$I5)) | X5: =Inputs!$B$35 | Y5: =B5*X5 | Z5: =C5*X5 | AA5: =Inputs!$B$35 | AB5: concrete
A6: Rebar in all concrete | B6: =Inputs!$B$11*Inputs!$B$17/1000*Inputs!$B$2 | C6: =Inputs!$C$11*Inputs!$C$17/1000*Inputs!$C$2 | D6: =D5+B6 | E6: =E5+C6 | F6: 0 | G6: 0 | H6: 0 | I6: =Inputs!$B$30*Inputs!$B$32+(1-Inputs!$B$30)*Inputs!$B$31 | J6: =B6*SUM($F6:$I6) | K6: =C6*SUM($F6:$I6) | L6: =J6*Inputs!$B$40 | M6: =K6*Inputs!$C$40 | N6: Rebar follows the concrete it sits in: foundation share × 90% + slab share × 75% | O6: =C6-K6 | P6: =IF(SUM($F6:$I6)=0,0,L6*F6/SUM($F6:$I6)) | Q6: =IF(SUM($F6:$I6)=0,0,L6*G6/SUM($F6:$I6)) | R6: =IF(SUM($F6:$I6)=0,0,L6*H6/SUM($F6:$I6)) | S6: =IF(SUM($F6:$I6)=0,0,L6*I6/SUM($F6:$I6)) | T6: =IF(SUM($F6:$I6)=0,0,M6*F6/SUM($F6:$I6)) | U6: =IF(SUM($F6:$I6)=0,0,M6*G6/SUM($F6:$I6)) | V6: =IF(SUM($F6:$I6)=0,0,M6*H6/SUM($F6:$I6)) | W6: =IF(SUM($F6:$I6)=0,0,M6*I6/SUM($F6:$I6)) | X6: =Inputs!$B$44 | Y6: =B6*X6 | Z6: =C6*X6 | AA6: =Inputs!$C$45 | AB6: steel
A7: Structural steel — primary frame (columns, girders) | B7: =Inputs!$B$15*(1-Inputs!$B$16)*Inputs!$B$2 | C7: =Inputs!$C$15*(1-Inputs!$C$16)*Inputs!$C$2 | D7: =D6+B7 | E7: =E6+C7 | F7: 0 | G7: 0 | H7: 1 | I7: 0 | J7: =B7*SUM($F7:$I7) | K7: =C7*SUM($F7:$I7) | L7: =J7*Inputs!$B$40 | M7: =K7*Inputs!$C$40 | N7: ICC-ES via the mass-timber qualification pathway; FM acceptance; E119 | O7: =C7-K7 | P7: =IF(SUM($F7:$I7)=0,0,L7*F7/SUM($F7:$I7)) | Q7: =IF(SUM($F7:$I7)=0,0,L7*G7/SUM($F7:$I7)) | R7: =IF(SUM($F7:$I7)=0,0,L7*H7/SUM($F7:$I7)) | S7: =IF(SUM($F7:$I7)=0,0,L7*I7/SUM($F7:$I7)) | T7: =IF(SUM($F7:$I7)=0,0,M7*F7/SUM($F7:$I7)) | U7: =IF(SUM($F7:$I7)=0,0,M7*G7/SUM($F7:$I7)) | V7: =IF(SUM($F7:$I7)=0,0,M7*H7/SUM($F7:$I7)) | W7: =IF(SUM($F7:$I7)=0,0,M7*I7/SUM($F7:$I7)) | X7: =Inputs!$B$44 | Y7: =B7*X7 | Z7: =C7*X7 | AA7: =Inputs!$C$45 | AB7: steel
A8: Structural steel — roof trusses, joists, roof deck, girts | B8: =Inputs!$B$15*Inputs!$B$16*Inputs!$B$2 | C8: =Inputs!$C$15*Inputs!$C$16*Inputs!$C$2 | D8: =D7+B8 | E8: =E7+C8 | F8: 0 | G8: 0 | H8: 1 | I8: 0 | J8: =B8*SUM($F8:$I8) | K8: =C8*SUM($F8:$I8) | L8: =J8*Inputs!$B$40 | M8: =K8*Inputs!$C$40 | N8: Design values and connection data; trusses carry no fire-resistance requirement | O8: =C8-K8 | P8: =IF(SUM($F8:$I8)=0,0,L8*F8/SUM($F8:$I8)) | Q8: =IF(SUM($F8:$I8)=0,0,L8*G8/SUM($F8:$I8)) | R8: =IF(SUM($F8:$I8)=0,0,L8*H8/SUM($F8:$I8)) | S8: =IF(SUM($F8:$I8)=0,0,L8*I8/SUM($F8:$I8)) | T8: =IF(SUM($F8:$I8)=0,0,M8*F8/SUM($F8:$I8)) | U8: =IF(SUM($F8:$I8)=0,0,M8*G8/SUM($F8:$I8)) | V8: =IF(SUM($F8:$I8)=0,0,M8*H8/SUM($F8:$I8)) | W8: =IF(SUM($F8:$I8)=0,0,M8*I8/SUM($F8:$I8)) | X8: =Inputs!$B$44 | Y8: =B8*X8 | Z8: =C8*X8 | AA8: =Inputs!$C$45 | AB8: steel
A9: Exterior skins — metal panel / IMP (metal-panel case) | B9: =(1-Inputs!$B$13)*Derived!B4*Inputs!$B$19/1000 | C9: =(1-Inputs!$C$13)*Derived!C4*Inputs!$C$19/1000 | D9: =D8+B9 | E9: =E8+C9 | F9: 1 | G9: 0 | H9: 0 | I9: 0 | J9: =B9*SUM($F9:$I9) | K9: =C9*SUM($F9:$I9) | L9: =SUM($F9:$I9)*(1-Inputs!$B$13)*Derived!B3*Derived!B6/1000 | M9: =SUM($F9:$I9)*(1-Inputs!$C$13)*Derived!C3*Derived!C6/1000 | N9: Shipping now; area-for-area rain screen | O9: =C9-K9 | P9: =IF(SUM($F9:$I9)=0,0,L9*F9/SUM($F9:$I9)) | Q9: =IF(SUM($F9:$I9)=0,0,L9*G9/SUM($F9:$I9)) | R9: =IF(SUM($F9:$I9)=0,0,L9*H9/SUM($F9:$I9)) | S9: =IF(SUM($F9:$I9)=0,0,L9*I9/SUM($F9:$I9)) | T9: =IF(SUM($F9:$I9)=0,0,M9*F9/SUM($F9:$I9)) | U9: =IF(SUM($F9:$I9)=0,0,M9*G9/SUM($F9:$I9)) | V9: =IF(SUM($F9:$I9)=0,0,M9*H9/SUM($F9:$I9)) | W9: =IF(SUM($F9:$I9)=0,0,M9*I9/SUM($F9:$I9)) | X9: =Inputs!$B$44 | Y9: =B9*X9 | Z9: =C9*X9 | AA9: =Inputs!$C$45 | AB9: steel
A10: Louvers and yard / mechanical screens | B10: =Inputs!$B$6*0.092903*Inputs!$B$20/1000 | C10: =Inputs!$C$6*0.092903*Inputs!$C$20/1000 | D10: =D9+B10 | E10: =E9+C10 | F10: 1 | G10: 0 | H10: 0 | I10: 0 | J10: =B10*SUM($F10:$I10) | K10: =C10*SUM($F10:$I10) | L10: =SUM($F10:$I10)*Inputs!$B$6*Derived!B6/1000 | M10: =SUM($F10:$I10)*Inputs!$C$6*Derived!C6/1000 | N10: Shipping now | O10: =C10-K10 | P10: =IF(SUM($F10:$I10)=0,0,L10*F10/SUM($F10:$I10)) | Q10: =IF(SUM($F10:$I10)=0,0,L10*G10/SUM($F10:$I10)) | R10: =IF(SUM($F10:$I10)=0,0,L10*H10/SUM($F10:$I10)) | S10: =IF(SUM($F10:$I10)=0,0,L10*I10/SUM($F10:$I10)) | T10: =IF(SUM($F10:$I10)=0,0,M10*F10/SUM($F10:$I10)) | U10: =IF(SUM($F10:$I10)=0,0,M10*G10/SUM($F10:$I10)) | V10: =IF(SUM($F10:$I10)=0,0,M10*H10/SUM($F10:$I10)) | W10: =IF(SUM($F10:$I10)=0,0,M10*I10/SUM($F10:$I10)) | X10: =Inputs!$B$44 | Y10: =B10*X10 | Z10: =C10*X10 | AA10: =Inputs!$C$45 | AB10: steel
A11: Security and staff-area fencing | B11: =Inputs!$B$7*1000*Inputs!$B$21/1000 | C11: =Inputs!$C$7*1000*Inputs!$C$21/1000 | D11: =D10+B11 | E11: =E10+C11 | F11: 1 | G11: 0 | H11: 0 | I11: 0 | J11: =B11*SUM($F11:$I11) | K11: =C11*SUM($F11:$I11) | L11: =SUM($F11:$I11)*Derived!B5*Derived!B6/1000 | M11: =SUM($F11:$I11)*Derived!C5*Derived!C6/1000 | N11: Shipping now — the Microsoft near-term list | O11: =C11-K11 | P11: =IF(SUM($F11:$I11)=0,0,L11*F11/SUM($F11:$I11)) | Q11: =IF(SUM($F11:$I11)=0,0,L11*G11/SUM($F11:$I11)) | R11: =IF(SUM($F11:$I11)=0,0,L11*H11/SUM($F11:$I11)) | S11: =IF(SUM($F11:$I11)=0,0,L11*I11/SUM($F11:$I11)) | T11: =IF(SUM($F11:$I11)=0,0,M11*F11/SUM($F11:$I11)) | U11: =IF(SUM($F11:$I11)=0,0,M11*G11/SUM($F11:$I11)) | V11: =IF(SUM($F11:$I11)=0,0,M11*H11/SUM($F11:$I11)) | W11: =IF(SUM($F11:$I11)=0,0,M11*I11/SUM($F11:$I11)) | X11: =Inputs!$B$44 | Y11: =B11*X11 | Z11: =C11*X11 | AA11: =Inputs!$C$45 | AB11: steel
A12: CONTENTS — FIT-OUT AND EQUIPMENT
A13: Platforms, walkways, mezzanines, railings, tray supports | B13: =Inputs!$B$18*Inputs!$B$2 | C13: =Inputs!$C$18*Inputs!$C$2 | D13: =D11+B13 | E13: =E11+C13 | F13: 0 | G13: 1 | H13: 0 | I13: 0 | J13: =B13*SUM($F13:$I13) | K13: =C13*SUM($F13:$I13) | L13: =J13*Inputs!$B$40 | M13: =K13*Inputs!$C$40 | N13: Published design values; IBC 1607 for railings | O13: =C13-K13 | P13: =IF(SUM($F13:$I13)=0,0,L13*F13/SUM($F13:$I13)) | Q13: =IF(SUM($F13:$I13)=0,0,L13*G13/SUM($F13:$I13)) | R13: =IF(SUM($F13:$I13)=0,0,L13*H13/SUM($F13:$I13)) | S13: =IF(SUM($F13:$I13)=0,0,L13*I13/SUM($F13:$I13)) | T13: =IF(SUM($F13:$I13)=0,0,M13*F13/SUM($F13:$I13)) | U13: =IF(SUM($F13:$I13)=0,0,M13*G13/SUM($F13:$I13)) | V13: =IF(SUM($F13:$I13)=0,0,M13*H13/SUM($F13:$I13)) | W13: =IF(SUM($F13:$I13)=0,0,M13*I13/SUM($F13:$I13)) | X13: =Inputs!$B$44 | Y13: =B13*X13 | Z13: =C13*X13 | AA13: =Inputs!$C$45 | AB13: steel
A14: Acoustic barriers, enclosures, HVAC separations | B14: =Inputs!$B$22*Inputs!$B$2 | C14: =Inputs!$C$22*Inputs!$C$2 | D14: =D13+B14 | E14: =E13+C14 | F14: 0 | G14: 1 | H14: 0 | I14: 0 | J14: =B14*SUM($F14:$I14) | K14: =C14*SUM($F14:$I14) | L14: =J14*Inputs!$B$40 | M14: =K14*Inputs!$C$40 | N14: STC / OITC lab and field data | O14: =C14-K14 | P14: =IF(SUM($F14:$I14)=0,0,L14*F14/SUM($F14:$I14)) | Q14: =IF(SUM($F14:$I14)=0,0,L14*G14/SUM($F14:$I14)) | R14: =IF(SUM($F14:$I14)=0,0,L14*H14/SUM($F14:$I14)) | S14: =IF(SUM($F14:$I14)=0,0,L14*I14/SUM($F14:$I14)) | T14: =IF(SUM($F14:$I14)=0,0,M14*F14/SUM($F14:$I14)) | U14: =IF(SUM($F14:$I14)=0,0,M14*G14/SUM($F14:$I14)) | V14: =IF(SUM($F14:$I14)=0,0,M14*H14/SUM($F14:$I14)) | W14: =IF(SUM($F14:$I14)=0,0,M14*I14/SUM($F14:$I14)) | X14: =Inputs!$B$44 | Y14: =B14*X14 | Z14: =C14*X14 | AA14: =Inputs!$C$45 | AB14: steel
A15: Racking and equipment supports | B15: =Inputs!$B$23*Inputs!$B$2 | C15: =Inputs!$C$23*Inputs!$C$2 | D15: =D14+B15 | E15: =E14+C15 | F15: 0 | G15: 1 | H15: 0 | I15: 0 | J15: =B15*SUM($F15:$I15) | K15: =C15*SUM($F15:$I15) | L15: =J15*Inputs!$B$40 | M15: =K15*Inputs!$C$40 | N15: A few months of design and load-data development (Alex 2026-09-04) | O15: =C15-K15 | P15: =IF(SUM($F15:$I15)=0,0,L15*F15/SUM($F15:$I15)) | Q15: =IF(SUM($F15:$I15)=0,0,L15*G15/SUM($F15:$I15)) | R15: =IF(SUM($F15:$I15)=0,0,L15*H15/SUM($F15:$I15)) | S15: =IF(SUM($F15:$I15)=0,0,L15*I15/SUM($F15:$I15)) | T15: =IF(SUM($F15:$I15)=0,0,M15*F15/SUM($F15:$I15)) | U15: =IF(SUM($F15:$I15)=0,0,M15*G15/SUM($F15:$I15)) | V15: =IF(SUM($F15:$I15)=0,0,M15*H15/SUM($F15:$I15)) | W15: =IF(SUM($F15:$I15)=0,0,M15*I15/SUM($F15:$I15)) | X15: =Inputs!$B$44 | Y15: =B15*X15 | Z15: =C15*X15 | AA15: =Inputs!$C$45 | AB15: steel
A16: Other tray, containment, doors, misc. metals | B16: =Inputs!$B$24*Inputs!$B$2 | C16: =Inputs!$C$24*Inputs!$C$2 | D16: =D15+B16 | E16: =E15+C16 | F16: 0 | G16: =Inputs!$B$42 | H16: 0 | I16: 0 | J16: =B16*SUM($F16:$I16) | K16: =C16*SUM($F16:$I16) | L16: =J16*Inputs!$B$40 | M16: =K16*Inputs!$C$40 | N16: Partial; UL 10C for rated doors | O16: =C16-K16 | P16: =IF(SUM($F16:$I16)=0,0,L16*F16/SUM($F16:$I16)) | Q16: =IF(SUM($F16:$I16)=0,0,L16*G16/SUM($F16:$I16)) | R16: =IF(SUM($F16:$I16)=0,0,L16*H16/SUM($F16:$I16)) | S16: =IF(SUM($F16:$I16)=0,0,L16*I16/SUM($F16:$I16)) | T16: =IF(SUM($F16:$I16)=0,0,M16*F16/SUM($F16:$I16)) | U16: =IF(SUM($F16:$I16)=0,0,M16*G16/SUM($F16:$I16)) | V16: =IF(SUM($F16:$I16)=0,0,M16*H16/SUM($F16:$I16)) | W16: =IF(SUM($F16:$I16)=0,0,M16*I16/SUM($F16:$I16)) | X16: =Inputs!$B$44 | Y16: =B16*X16 | Z16: =C16*X16 | AA16: =Inputs!$C$45 | AB16: steel
A17: Ducting, plenums and air-distribution sheet metal | B17: =Inputs!$B$34*Inputs!$B$2 | C17: =Inputs!$C$34*Inputs!$C$2 | D17: =D16+B17 | E17: =E16+C17 | F17: 0 | G17: 0 | H17: 1 | I17: 0 | J17: =B17*SUM($F17:$I17) | K17: =C17*SUM($F17:$I17) | L17: =J17*Inputs!$B$40 | M17: =K17*Inputs!$C$40 | N17: NFPA 90A / UL 181 noncombustibility expectations for in-airstream components — the hardest gate in this row set | O17: =C17-K17 | P17: =IF(SUM($F17:$I17)=0,0,L17*F17/SUM($F17:$I17)) | Q17: =IF(SUM($F17:$I17)=0,0,L17*G17/SUM($F17:$I17)) | R17: =IF(SUM($F17:$I17)=0,0,L17*H17/SUM($F17:$I17)) | S17: =IF(SUM($F17:$I17)=0,0,L17*I17/SUM($F17:$I17)) | T17: =IF(SUM($F17:$I17)=0,0,M17*F17/SUM($F17:$I17)) | U17: =IF(SUM($F17:$I17)=0,0,M17*G17/SUM($F17:$I17)) | V17: =IF(SUM($F17:$I17)=0,0,M17*H17/SUM($F17:$I17)) | W17: =IF(SUM($F17:$I17)=0,0,M17*I17/SUM($F17:$I17)) | X17: =Inputs!$B$44 | Y17: =B17*X17 | Z17: =C17*X17 | AA17: =Inputs!$C$45 | AB17: steel
A18: Interior finishes, backplanes, trim (admin / office) | B18: =Inputs!$B$25*Inputs!$B$2 | C18: =Inputs!$C$25*Inputs!$C$2 | D18: =D17+B18 | E18: =E17+C18 | F18: 1 | G18: 0 | H18: 0 | I18: 0 | J18: =B18*SUM($F18:$I18) | K18: =C18*SUM($F18:$I18) | L18: =SUM($F18:$I18)*(Inputs!$B$9+Inputs!$B$10)*Derived!B6/1000 | M18: =SUM($F18:$I18)*(Inputs!$C$9+Inputs!$C$10)*Derived!C6/1000 | N18: E84 Class A finish; backplanes UL 94 yellow card (not yet started) | O18: =C18-K18 | P18: =IF(SUM($F18:$I18)=0,0,L18*F18/SUM($F18:$I18)) | Q18: =IF(SUM($F18:$I18)=0,0,L18*G18/SUM($F18:$I18)) | R18: =IF(SUM($F18:$I18)=0,0,L18*H18/SUM($F18:$I18)) | S18: =IF(SUM($F18:$I18)=0,0,L18*I18/SUM($F18:$I18)) | T18: =IF(SUM($F18:$I18)=0,0,M18*F18/SUM($F18:$I18)) | U18: =IF(SUM($F18:$I18)=0,0,M18*G18/SUM($F18:$I18)) | V18: =IF(SUM($F18:$I18)=0,0,M18*H18/SUM($F18:$I18)) | W18: =IF(SUM($F18:$I18)=0,0,M18*I18/SUM($F18:$I18)) | X18: =Inputs!$B$48 | Y18: =B18*X18 | Z18: =C18*X18 | AA18: =Inputs!$B$48 | AB18: mixed
A19: Electrical equipment and conductors | B19: =Inputs!$B$26*Inputs!$B$2 | C19: =Inputs!$C$26*Inputs!$C$2 | D19: =D18+B19 | E19: =E18+C19 | F19: 0 | G19: 0 | H19: 0 | I19: 0 | J19: =B19*SUM($F19:$I19) | K19: =C19*SUM($F19:$I19) | L19: =0 | M19: =0 | N19: Gensets, transformers, switchgear, batteries, copper | O19: =C19-K19 | P19: =IF(SUM($F19:$I19)=0,0,L19*F19/SUM($F19:$I19)) | Q19: =IF(SUM($F19:$I19)=0,0,L19*G19/SUM($F19:$I19)) | R19: =IF(SUM($F19:$I19)=0,0,L19*H19/SUM($F19:$I19)) | S19: =IF(SUM($F19:$I19)=0,0,L19*I19/SUM($F19:$I19)) | T19: =IF(SUM($F19:$I19)=0,0,M19*F19/SUM($F19:$I19)) | U19: =IF(SUM($F19:$I19)=0,0,M19*G19/SUM($F19:$I19)) | V19: =IF(SUM($F19:$I19)=0,0,M19*H19/SUM($F19:$I19)) | W19: =IF(SUM($F19:$I19)=0,0,M19*I19/SUM($F19:$I19)) | X19: =Inputs!$B$49*Inputs!$B$44 | Y19: =B19*X19 | Z19: =C19*X19 | AA19: =Inputs!$B$49*Inputs!$C$45 | AB19: equipment
A20: Mechanical equipment, piping, loop water | B20: =Inputs!$B$27*Inputs!$B$2 | C20: =Inputs!$C$27*Inputs!$C$2 | D20: =D19+B20 | E20: =E19+C20 | F20: 0 | G20: 0 | H20: 0 | I20: 0 | J20: =B20*SUM($F20:$I20) | K20: =C20*SUM($F20:$I20) | L20: =0 | M20: =0 | N20: Chillers, fan walls, coolers, piping (ductwork is its own row) | O20: =C20-K20 | P20: =IF(SUM($F20:$I20)=0,0,L20*F20/SUM($F20:$I20)) | Q20: =IF(SUM($F20:$I20)=0,0,L20*G20/SUM($F20:$I20)) | R20: =IF(SUM($F20:$I20)=0,0,L20*H20/SUM($F20:$I20)) | S20: =IF(SUM($F20:$I20)=0,0,L20*I20/SUM($F20:$I20)) | T20: =IF(SUM($F20:$I20)=0,0,M20*F20/SUM($F20:$I20)) | U20: =IF(SUM($F20:$I20)=0,0,M20*G20/SUM($F20:$I20)) | V20: =IF(SUM($F20:$I20)=0,0,M20*H20/SUM($F20:$I20)) | W20: =IF(SUM($F20:$I20)=0,0,M20*I20/SUM($F20:$I20)) | X20: =Inputs!$B$50*Inputs!$B$44 | Y20: =B20*X20 | Z20: =C20*X20 | AA20: =Inputs!$B$50*Inputs!$C$45 | AB20: equipment
A21: IT — servers and racks | B21: =Inputs!$B$28*Inputs!$B$2 | C21: =Inputs!$C$28*Inputs!$C$2 | D21: =D20+B21 | E21: =E20+C21 | F21: 0 | G21: 0 | H21: 0 | I21: =Inputs!$B$29 | J21: =B21*SUM($F21:$I21) | K21: =C21*SUM($F21:$I21) | L21: =J21*Inputs!$B$40 | M21: =K21*Inputs!$C$40 | N21: Server and equipment enclosures only (40% of IT mass, estimate); electronics never. Rack masses [H]; aggregate [L] | O21: =C21-K21 | P21: =IF(SUM($F21:$I21)=0,0,L21*F21/SUM($F21:$I21)) | Q21: =IF(SUM($F21:$I21)=0,0,L21*G21/SUM($F21:$I21)) | R21: =IF(SUM($F21:$I21)=0,0,L21*H21/SUM($F21:$I21)) | S21: =IF(SUM($F21:$I21)=0,0,L21*I21/SUM($F21:$I21)) | T21: =IF(SUM($F21:$I21)=0,0,M21*F21/SUM($F21:$I21)) | U21: =IF(SUM($F21:$I21)=0,0,M21*G21/SUM($F21:$I21)) | V21: =IF(SUM($F21:$I21)=0,0,M21*H21/SUM($F21:$I21)) | W21: =IF(SUM($F21:$I21)=0,0,M21*I21/SUM($F21:$I21)) | X21: =Inputs!$B$51*Inputs!$B$44 | Y21: =B21*X21 | Z21: =C21*X21 | AA21: =Inputs!$B$51*Inputs!$C$45 | AB21: equipment
A23: SUMMARY — per data center
A24: Total mass, building and contents (tons) | B24: =SUM(B3:B21) | C24: =SUM(C3:C21)
A25: Total excluding concrete (tons) | B25: =B24-B3-B4-B5 | C25: =C24-C3-C4-C5
A27: Replaced by SUPERWOOD, by horizon
A28: Immediate — incumbent mass replaced (tons) | B28: =SUMPRODUCT(B3:B21,F3:F21) | C28: =SUMPRODUCT(C3:C21,F3:F21)
A29: Immediate — SUPERWOOD required (tons) | B29: =SUM(P3:P21) | C29: =SUM(T3:T21)
A30: Immediate — SUPERWOOD required (sf) | B30: =B29*1000/Derived!B6 | C30: =C29*1000/Derived!C6
A31: Immediate — years of SuperMill One output | B31: =B29/Derived!B7 | C31: =C29/Derived!C7
A33: Soon — incumbent mass replaced (tons) | B33: =SUMPRODUCT(B3:B21,G3:G21) | C33: =SUMPRODUCT(C3:C21,G3:G21)
A34: Soon — SUPERWOOD required (tons) | B34: =SUM(Q3:Q21) | C34: =SUM(U3:U21)
A35: Soon — years of SuperMill Two output | B35: =B34/Derived!B8 | C35: =C34/Derived!C8
A37: Medium term — incumbent mass replaced (tons) | B37: =SUMPRODUCT(B3:B21,H3:H21) | C37: =SUMPRODUCT(C3:C21,H3:H21)
A38: Medium term — SUPERWOOD required (tons) | B38: =SUM(R3:R21) | C38: =SUM(V3:V21)
A39: Medium term — years of SuperMill Two output | B39: =B38/Derived!B8 | C39: =C38/Derived!C8
A41: Long term — incumbent mass replaced (tons) | B41: =SUMPRODUCT(B3:B21,I3:I21) | C41: =SUMPRODUCT(C3:C21,I3:I21)
A42: Long term — SUPERWOOD required (tons) | B42: =SUM(S3:S21) | C42: =SUM(W3:W21)
A43: Long term — years of SuperMill Two output | B43: =B42/Derived!B8 | C43: =C42/Derived!C8
A45: Cumulative incumbent mass replaced (tons) | B45: =SUM(J3:J21) | C45: =SUM(K3:K21)
A46: Cumulative SUPERWOOD required (tons) | B46: =SUM(L3:L21) | C46: =SUM(M3:M21)
...

Sheet Derived
A1: Quantity | B1: Low | C1: High | D1: Unit
A2: Number of buildings | B2: =Inputs!$B$3*Inputs!$B$2/Inputs!$B$4 | C2: =Inputs!$C$3*Inputs!$C$2/Inputs!$C$4 | D2: count
A3: Exterior wall area, sf | B3: =B2*Inputs!$B$5 | C3: =C2*Inputs!$C$5 | D3: sf
A4: Exterior wall area, m² | B4: =B3*0.092903 | C4: =C3*0.092903 | D4: m²
A5: Fence face area, sf | B5: =Inputs!$B$7*1000*Inputs!$B$8/0.092903 | C5: =Inputs!$C$7*1000*Inputs!$C$8/0.092903 | D5: sf
A6: SUPERWOOD board mass per sf | B6: =Inputs!$B$36/1000*Inputs!$B$37*0.092903 | C6: =Inputs!$C$36/1000*Inputs!$C$37*0.092903 | D6: kg/sf
A7: SuperMill One output in tonnes | B7: =Inputs!$B$38*B6/1000 | C7: =Inputs!$C$38*C6/1000 | D7: t/yr
A8: SuperMill Two output in tonnes | B8: =Inputs!$B$39*B6/1000 | C8: =Inputs!$C$39*C6/1000 | D8: t/yr

Sheet Carbon
A1: Horizon | B1: Low incumbent emissions avoided (t CO₂e) | C1: High | D1: Low SUPERWOOD manufacturing (t CO₂e) | E1: High | F1: Low net reduction | G1: High | H1: Low net vs EAF steel | I1: High | J1: Low biogenic stored (separate) | K1: High
A2: Immediate (steel) | B2: =SUMPRODUCT('1 GW data center'!B3:B21,'1 GW data center'!F3:F21,'1 GW data center'!X3:X21) | C2: =SUMPRODUCT('1 GW data center'!C3:C21,'1 GW data center'!F3:F21,'1 GW data center'!X3:X21) | D2: ='1 GW data center'!B29*Inputs!$B$46 | E2: ='1 GW data center'!C29*Inputs!$C$46 | F2: =B2-D2 | G2: =C2-E2 | H2: =SUMPRODUCT('1 GW data center'!B3:B21,'1 GW data center'!F3:F21,'1 GW data center'!AA3:AA21)-D2 | I2: =SUMPRODUCT('1 GW data center'!C3:C21,'1 GW data center'!F3:F21,'1 GW data center'!AA3:AA21)-E2 | J2: ='1 GW data center'!B29*Inputs!$B$47 | K2: ='1 GW data center'!C29*Inputs!$C$47
A3: Soon (steel) | B3: =SUMPRODUCT('1 GW data center'!B3:B21,'1 GW data center'!G3:G21,'1 GW data center'!X3:X21) | C3: =SUMPRODUCT('1 GW data center'!C3:C21,'1 GW data center'!G3:G21,'1 GW data center'!X3:X21) | D3: ='1 GW data center'!B34*Inputs!$B$46 | E3: ='1 GW data center'!C34*Inputs!$C$46 | F3: =B3-D3 | G3: =C3-E3 | H3: =SUMPRODUCT('1 GW data center'!B3:B21,'1 GW data center'!G3:G21,'1 GW data center'!AA3:AA21)-D3 | I3: =SUMPRODUCT('1 GW data center'!C3:C21,'1 GW data center'!G3:G21,'1 GW data center'!AA3:AA21)-E3 | J3: ='1 GW data center'!B34*Inputs!$B$47 | K3: ='1 GW data center'!C34*Inputs!$C$47
A4: Medium term (steel) | B4: =SUMPRODUCT('1 GW data center'!B3:B21,'1 GW data center'!H3:H21,'1 GW data center'!X3:X21) | C4: =SUMPRODUCT('1 GW data center'!C3:C21,'1 GW data center'!H3:H21,'1 GW data center'!X3:X21) | D4: ='1 GW data center'!B38*Inputs!$B$46 | E4: ='1 GW data center'!C38*Inputs!$C$46 | F4: =B4-D4 | G4: =C4-E4 | H4: =SUMPRODUCT('1 GW data center'!B3:B21,'1 GW data center'!H3:H21,'1 GW data center'!AA3:AA21)-D4 | I4: =SUMPRODUCT('1 GW data center'!C3:C21,'1 GW data center'!H3:H21,'1 GW data center'!AA3:AA21)-E4 | J4: ='1 GW data center'!B38*Inputs!$B$47 | K4: ='1 GW data center'!C38*Inputs!$C$47
A5: Long term (concrete, rebar, server enclosures) | B5: =SUMPRODUCT('1 GW data center'!B3:B21,'1 GW data center'!I3:I21,'1 GW data center'!X3:X21) | C5: =SUMPRODUCT('1 GW data center'!C3:C21,'1 GW data center'!I3:I21,'1 GW data center'!X3:X21) | D5: ='1 GW data center'!B42*Inputs!$B$46 | E5: ='1 GW data center'!C42*Inputs!$C$46 | F5: =B5-D5 | G5: =C5-E5 | H5: =SUMPRODUCT('1 GW data center'!B3:B21,'1 GW data center'!I3:I21,'1 GW data center'!AA3:AA21)-D5 | I5: =SUMPRODUCT('1 GW data center'!C3:C21,'1 GW data center'!I3:I21,'1 GW data center'!AA3:AA21)-E5 | J5: ='1 GW data center'!B42*Inputs!$B$47 | K5: ='1 GW data center'!C42*Inputs!$C$47
A7: Pre-LCA projections (LCA under way with Prof. Ming Hu, University of Notre Dame). Each row is valued at its own factor (column X on the main sheet): concrete rows at co2_conc, steel rows including rebar at co2_steel, interior finishes at co2_mixed; equipment rows (including the long-term server enclosures) carry no factor, so the long-term row counts concrete and rebar only. The EAF column revalues steel rows at the recycled-steel factor (high end). Equipment rows carry no factor. Biogenic storage reported separately (EN 15804 module C).

Sheet Steel share
A1: Above-ground component (contents included) | B1: Low tons | C1: High tons | D1: Steel fraction — low | E1: Steel fraction — high | F1: Low steel tons | G1: High steel tons | H1: Basis for the fraction
A2: Precast / tilt-up perimeter walls (precast case) | B2: ='1 GW data center'!B5 | C2: ='1 GW data center'!C5 | D2: 0.03 | E2: 0.05 | F2: =B2*D2 | G2: =C2*E2 | H2: rebar in precast/tilt-up panels; row is zero unless Inputs walls_precast = 1
A3: Structural steel — primary frame (columns, girders) | B3: ='1 GW data center'!B7 | C3: ='1 GW data center'!C7 | D3: 1 | E3: 1 | F3: =B3*D3 | G3: =C3*E3 | H3: steel by definition
A4: Structural steel — roof trusses, joists, roof deck, girts | B4: ='1 GW data center'!B8 | C4: ='1 GW data center'!C8 | D4: 1 | E4: 1 | F4: =B4*D4 | G4: =C4*E4 | H4: steel by definition
A5: Exterior skins — metal panel / IMP (metal-panel case) | B5: ='1 GW data center'!B9 | C5: ='1 GW data center'!C9 | D5: 0.85 | E5: 0.95 | F5: =B5*D5 | G5: =C5*E5 | H5: steel-faced IMP; some aluminum
A6: Louvers and yard / mechanical screens | B6: ='1 GW data center'!B10 | C6: ='1 GW data center'!C10 | D6: 0.4 | E6: 0.7 | F6: =B6*D6 | G6: =C6*E6 | H6: aluminum common
A7: Security and staff-area fencing | B7: ='1 GW data center'!B11 | C7: ='1 GW data center'!C11 | D7: 0.9 | E7: 1 | F7: =B7*D7 | G7: =C7*E7 | H7: chain-link, palisade, posts
A8: Platforms, walkways, mezzanines, railings, tray supports | B8: ='1 GW data center'!B13 | C8: ='1 GW data center'!C13 | D8: 0.95 | E8: 1 | F8: =B8*D8 | G8: =C8*E8 | H8: structural and misc. steel
A9: Acoustic barriers, enclosures, HVAC separations | B9: ='1 GW data center'!B14 | C9: ='1 GW data center'!C14 | D9: 0.7 | E9: 0.9 | F9: =B9*D9 | G9: =C9*E9 | H9: steel panels with absorptive fill
A10: Racking and equipment supports | B10: ='1 GW data center'!B15 | C10: ='1 GW data center'!C15 | D10: 0.95 | E10: 1 | F10: =B10*D10 | G10: =C10*E10 | H10: steel
A11: Other tray, containment, doors, misc. metals | B11: ='1 GW data center'!B16 | C11: ='1 GW data center'!C16 | D11: 0.85 | E11: 0.95 | F11: =B11*D11 | G11: =C11*E11 | H11: mostly steel, some aluminum
A12: Ducting, plenums and air-distribution sheet metal | B12: ='1 GW data center'!B17 | C12: ='1 GW data center'!C17 | D12: 0.95 | E12: 1 | F12: =B12*D12 | G12: =C12*E12 | H12: galvanized steel
A13: Interior finishes, backplanes, trim (admin / office) | B13: ='1 GW data center'!B18 | C13: ='1 GW data center'!C18 | D13: 0.2 | E13: 0.4 | F13: =B13*D13 | G13: =C13*E13 | H13: gypsum, wood, steel studs
A14: Electrical equipment and conductors | B14: ='1 GW data center'!B19 | C14: ='1 GW data center'!C19 | D14: 0.5 | E14: 0.65 | F14: =B14*D14 | G14: =C14*E14 | H14: enclosures, cores, gensets, switchgear; rest copper, oil, batteries
A15: Mechanical equipment, piping, loop water | B15: ='1 GW data center'!B20 | C15: ='1 GW data center'!C20 | D15: 0.45 | E15: 0.65 | F15: =B15*D15 | G15: =C15*E15 | H15: chillers, piping steel; water, copper, refrigerant not
A16: IT — servers and racks | B16: ='1 GW data center'!B21 | C16: ='1 GW data center'!C21 | D16: 0.4 | E16: 0.6 | F16: =B16*D16 | G16: =C16*E16 | H16: steel chassis and racks; aluminum, PCBs, copper
A18: Above-ground mass, contents included (tons) | B18: =SUM(B2:B16) | C18: =SUM(C2:C16)
A19: Steel in it (tons) | B19: =SUM(F2:F16) | C19: =SUM(G2:G16)
A20: Steel share of above-ground mass | B20: =B19/B18 | C20: =C19/C18
A21: Steel share including slab rebar (at-grade steel) | B21: =(B19+'1 GW data center'!B6)/(B18+'1 GW data center'!B6) | C21: =(C19+'1 GW data center'!C6)/(C18+'1 GW data center'!C6)
A22: Structure and envelope only (first five rows) | B22: =SUM(F2:F7)/SUM(B2:B7) | C22: =SUM(G2:G7)/SUM(C2:C7)
A24: WALL SYSTEM CASES (independent of the Inputs toggle)
A25: Tilt-up / precast wall mass if chosen (tons) | B25: =Derived!B4*Inputs!$B$14*Inputs!$B$12 | C25: =Derived!C4*Inputs!$C$14*Inputs!$C$12
A26: Metal-panel skin mass if chosen (tons) | B26: =Derived!B4*Inputs!$B$19/1000 | C26: =Derived!C4*Inputs!$C$19/1000
A27: Steel share — metal-panel walls | B27: =(B19-F2-F5+B26*D5)/(B18-B2-B5+B26) | C27: =(C19-F2-F5+C26*E5)/(C18-C2-C5+C26)
A28: Steel share — tilt-up / precast concrete walls | B28: =(B19-F2-F5+B25*D2)/(B18-B2-B5+B25) | C28: =(C19-G2-G5+C25*E2)/(C18-C2-C5+C25)
A30: Excludes slab on grade, paving and foundations. The wall system matters: the main block follows Inputs walls_precast (0 = metal panel, 1 = tilt-up/precast); the two case rows above force each wall system regardless of the toggle. Steel fractions per component are estimates [conf: L] (yellow cells). Printed band on the deck: 50–80% (Alex, 2026-09-04), covering both wall systems.
